Workbook

Sheet Sheet1
A3: Sum of Max | B3: Column Labels
A4: Row Labels | B4: Account ownership at a financial institution or with a mobile-money-service provider (% of population ages 15+) | C4: Account ownership at a financial institution or with a mobile-money-service provider, female (% of population ages 15+) | D4: Account ownership at a financial institution or with a mobile-money-service provider, male (% of population ages 15+) | E4: Account ownership at a financial institution or with a mobile-money-service provider, poorest 40% (% of population ages 15+) | F4: Account ownership at a financial institution or with a mobile-money-service provider, primary education or less (% of population ages 15+) | G4: Account ownership at a financial institution or with a mobile-money-service provider, young adults (% of population ages 15-24) | H4: Average working hours of children, working only, ages 7-14 (hours per week) | I4: Bribery incidence (% of firms experiencing at least one bribe payment request) | J4: Business extent of disclosure index (0=less disclosure to 10=more disclosure) | K4: Central government debt, total (% of GDP) | L4: Compulsory education, duration (years) | M4: Control of Corruption: Percentile Rank | N4: Coverage of social insurance programs in poorest quintile (% of population) | O4: Coverage of social safety net programs (% of population) | P4: Survival to age 65, female (% of cohort) | Q4: Technicians in R&D (per million people) | R4: Time required to start a business (days) | S4: Grand Total
A5: Afghanistan | B5: 9.65 | C5: 4.7 | D5: 14.79 | E5: 5.86 | F5: 5.18 | G5: 7.55 | H5: 0 | I5: 0 | J5: 8 | K5: 0 | L5: 9 | M5: 13.679245 | N5: 0 | O5: 0 | P5: 69.906777 | Q5: 0 | R5: 8.5 | S5: 156.81602
A6: Algeria | B6: 44.1 | C6: 31.19 | D6: 56.83 | E6: 31.91 | F6: 38.99 | G6: 26.72 | H6: 0 | I6: 0 | J6: 4 | K6: 0 | L6: 10 | M6: 30.188679 | N6: 0 | O6: 0 | P6: 87.509843 | Q6: 0 | R6: 18 | S6: 379.43852
A7: Angola | B7: 0 | C7: 0 | D7: 0 | E7: 0 | F7: 0 | G7: 0 | H7: 0 | I7: 0 | J7: 4 | K7: 0 | L7: 10 | M7: 30.188679 | N7: 0 | O7: 0 | P7: 68.636516 | Q7: 0 | R7: 36 | S7: 148.82519
A8: Argentina | B8: 71.63 | C8: 73.75 | D8: 69.56 | E8: 65.23 | F8: 57.1 | G8: 75.37 | H8: 0 | I8: 0 | J8: 7 | K8: 0 | L8: 14 | M8: 52.857143 | N8: 21.880785 | O8: 41.398729 | P8: 86.163347 | Q8: 0 | R8: 11.5 | S8: 647.44
A9: Australia | B9: 99.32 | C9: 100 | D9: 98.59 | E9: 98.3 | F9: 86.48 | G9: 100 | H9: 0 | I9: 0 | J9: 8 | K9: 70.010912 | L9: 11 | M9: 95.754715 | N9: 0 | O9: 0 | P9: 93.408547 | Q9: 0 | R9: 2 | S9: 862.86417
A10: Austria | B10: 99.95 | C10: 100 | D10: 99.9 | E10: 100 | F10: 100 | G10: 100 | H10: 0 | I10: 1.3 | J10: 5 | K10: 100.05679 | L10: 13 | M10: 90.952377 | N10: 0 | O10: 0 | P10: 93.266368 | Q10: 0 | R10: 21 | S10: 924.42553
A11: Azerbaijan | B11: 46.26 | C11: 38.84 | D11: 54.59 | E11: 35.58 | F11: 30.61 | G11: 36.38 | H11: 0 | I11: 12.1 | J11: 10 | K11: 22.189999 | L11: 10 | M11: 22.857143 | N11: 0 | O11: 0 | P11: 85.660171 | Q11: 0 | R11: 3.5 | S11: 408.56731
A12: Bahamas, The | B12: 0 | C12: 0 | D12: 0 | E12: 0 | F12: 0 | G12: 0 | H12: 0 | I12: 0 | J12: 3 | K12: 87.390332 | L12: 12 | M12: 88.20755 | N12: 0 | O12: 0 | P12: 82.828463 | Q12: 0 | R12: 11.5 | S12: 284.92634
A13: Bahrain | B13: 0 | C13: 0 | D13: 0 | E13: 0 | F13: 0 | G13: 0 | H13: 0 | I13: 0 | J13: 8 | K13: 111.59809 | L13: 9 | M13: 59.433964 | N13: 0 | O13: 0 | P13: 91.180304 | Q13: 0 | R13: 8.3 | S13: 287.51236
A14: Bangladesh | B14: 52.81 | C14: 43.46 | D14: 62.86 | E14: 48.65 | F14: 46.57 | G14: 47.8 | H14: 0 | I14: 23 | J14: 6 | K14: 0 | L14: 5 | M14: 18.095238 | N14: 0 | O14: 0 | P14: 81.950649 | Q14: 0 | R14: 19.5 | S14: 455.69589
A15: Barbados | B15: 0 | C15: 0 | D15: 0 | E15: 0 | F15: 0 | G15: 0 | H15: 0 | I15: 0 | J15: 2 | K15: 0 | L15: 11 | M15: 89.622643 | N15: 0 | O15: 0 | P15: 87.200547 | Q15: 0 | R15: 16 | S15: 205.82319
A16: Belarus | B16: 0 | C16: 0 | D16: 0 | E16: 0 | F16: 0 | G16: 0 | H16: 0 | I16: 0 | J16: 6 | K16: 33.244229 | L16: 11 | M16: 56.190475 | N16: 41.4284 | O16: 47.074578 | P16: 86.958716 | Q16: 0 | R16: 8.5 | S16: 290.3964
... A134: Grand Total | B134: 7780.6 | C134: 7484.95 | D134: 8086.96 | E134: 7139.18 | F134: 6725.53 | G134: 7219.62 | H134: 0 | I134: 713.1 | J134: 777.4 | K134: 4556.2343 | L134: 1287 | M134: 7091.5993 | N134: 294.0861 | O134: 1279.0125 | P134: 10888.583 | Q134: 0 | R134: 2378.8 | S134: 73702.656

Sheet Sample
A1: Row Labels | B1: Z Score Bank | C1: Account ownership at a financial institution or with a mobile-money-service provider (% of population ages 15+) | D1: Account ownership at a financial institution or with a mobile-money-service provider, female (% of population ages 15+) | E1: Account ownership at a financial institution or with a mobile-money-service provider, male (% of population ages 15+) | F1: Account ownership at a financial institution or with a mobile-money-service provider, poorest 40% (% of population ages 15+) | G1: Account ownership at a financial institution or with a mobile-money-service provider, primary education or less (% of population ages 15+) | H1: Account ownership at a financial institution or with a mobile-money-service provider, young adults (% of population ages 15-24) | I1: Average working hours of children, working only, ages 7-14 (hours per week) | J1: Bribery incidence (% of firms experiencing at least one bribe payment request) | K1: Business extent of disclosure index (0=less disclosure to 10=more disclosure) | L1: Central government debt, total (% of GDP) | M1: Compulsory education, duration (years) | N1: Control of Corruption: Percentile Rank | O1: Coverage of social insurance programs in poorest quintile (% of population) | P1: Coverage of social safety net programs (% of population) | Q1: Survival to age 65, female (% of cohort) | R1: Technicians in R&D (per million people) | S1: Time required to start a business (days) | T1: Grand Total
A2: Luxembourg | B2: =VLOOKUP(A2,'Bank Z Score'!$C$12:$P$226,14,FALSE) -> 51.66831 | C2: 0 | D2: 0 | E2: 0 | F2: 0 | G2: 0 | H2: 0 | I2: 0 | J2: 0 | K2: 6 | L2: 0 | M2: 12 | N2: 97.619049 | O2: 0 | P2: 0 | Q2: 92.554041 | R2: 0 | S2: 16.5 | T2: 224.67309
A3: Jordan | B3: =VLOOKUP(A3,'Bank Z Score'!$C$12:$P$226,14,FALSE) -> 50.10564 | C3: 47.12 | D3: 34.06 | E3: 58.6 | F3: 37.01 | G3: 38.71 | H3: 28.69 | I3: 0 | J3: 2.5 | K3: 4 | L3: 100.90828 | M3: 10 | N3: 58.57143 | O3: 0 | P3: 0 | Q3: 89.132172 | R3: 0 | S3: 12.5 | T3: 521.80189
A4: New Zealand | B4: =VLOOKUP(A4,'Bank Z Score'!$C$12:$P$226,14,FALSE) -> 44.78266 | C4: 98.75 | D4: 99.24 | E4: 98.23 | F4: 96.87 | G4: 96.53 | H4: 94.46 | I4: 0 | J4: 4 | K4: 10 | L4: 54.566672 | M4: 10 | N4: 100 | O4: 0 | P4: 0 | Q4: 92.227998 | R4: 0 | S4: 0.5 | T4: 855.37467
A5: Morocco | B5: =VLOOKUP(A5,'Bank Z Score'!$C$12:$P$226,14,FALSE) -> 42.40052 | C5: 44.37 | D5: 32.7 | E5: 55.97 | F5: 33.93 | G5: 36.91 | H5: 35.9 | I5: 0 | J5: 29.6 | K5: 9 | L5: 0 | M5: 9 | N5: 41.42857 | O5: 0 | P5: 0 | Q5: 86.611351 | R5: 0 | S5: 9 | T5: 424.41992
A6: Panama | B6: =VLOOKUP(A6,'Bank Z Score'!$C$12:$P$226,14,FALSE) -> 40.39326 | C6: 44.97 | D6: 43.11 | E6: 46.95 | F6: 32.41 | G6: 31.22 | H6: 40.42 | I6: 0 | J6: 0 | K6: 4 | L6: 0 | M6: 11 | N6: 30.476191 | O6: 5.7626014 | P6: 66.144764 | Q6: 88.722152 | R6: 0 | S6: 6 | T6: 451.18571
A7: Sweden | B7: =VLOOKUP(A7,'Bank Z Score'!$C$12:$P$226,14,FALSE) -> 39.34783 | C7: 99.69 | D7: 100 | E7: 99.39 | F7: 99.22 | G7: 100 | H7: 100 | I7: 0 | J7: 0 | K7: 8 | L7: 44.178007 | M7: 10 | N7: 98.095238 | O7: 0 | P7: 0 | Q7: 93.96868 | R7: 0 | S7: 7.5 | T7: 860.04192
A8: Tunisia | B8: =VLOOKUP(A8,'Bank Z Score'!$C$12:$P$226,14,FALSE) -> 38.68149 | C8: 36.85 | D8: 28.75 | E8: 45.14 | F8: 32.02 | G8: 29.26 | H8: 24.34 | I8: 0 | J8: 11.9 | K8: 6 | L8: 0 | M8: 9 | N8: 50.952381 | O8: 0 | P8: 0 | Q8: 89.196152 | R8: 0 | S8: 9 | T8: 372.40853
A9: Iraq | B9: =VLOOKUP(A9,'Bank Z Score'!$C$12:$P$226,14,FALSE) -> 37.25005 | C9: 18.57 | D9: 14.89 | E9: 22.21 | F9: 14.43 | G9: 15.48 | H9: 12.49 | I9: 0 | J9: 50.5 | K9: 4 | L9: 0 | M9: 6 | N9: 10.849056 | O9: 0 | P9: 0 | Q9: 81.023534 | R9: 0 | S9: 26.5 | T9: 276.94259
A10: Mongolia | B10: =VLOOKUP(A10,'Bank Z Score'!$C$12:$P$226,14,FALSE) -> 36.25018 | C10: 98.46 | D10: 98.97 | E10: 97.89 | F10: 98.29 | G10: 96.53 | H10: 95.45 | I10: 0 | J10: 24.7 | K10: 6 | L10: 73.936784 | M10: 12 | N10: 37.142857 | O10: 0 | P10: 0 | Q10: 83.016925 | R10: 0 | S10: 12 | T10: 834.38657
A11: Sri Lanka | B11: =VLOOKUP(A11,'Bank Z Score'!$C$12:$P$226,14,FALSE) -> 35.08618 | C11: 89.27 | D11: 89.28 | E11: 89.26 | F11: 87.08 | G11: 76.93 | H11: 86.4 | I11: 0 | J11: 0 | K11: 8 | L11: 0 | M11: 11 | N11: 44.285713 | O11: 2.8901919 | P11: 29.985752 | Q11: 90.438482 | R11: 0 | S11: 8 | T11: 712.82014
A12: Fiji | B12: =VLOOKUP(A12,'Bank Z Score'!$C$12:$P$226,14,FALSE) -> 33.01206 | C12: 0 | D12: 0 | E12: 0 | F12: 0 | G12: 0 | H12: 0 | I12: 0 | J12: 0 | K12: 2 | L12: 0 | M12: 0 | N12: 74.761902 | O12: 0 | P12: 0 | Q12: 69.209864 | R12: 0 | S12: 40 | T12: 185.97177
A13: Dominican Republic | B13: =VLOOKUP(A13,'Bank Z Score'!$C$12:$P$226,14,FALSE) -> 32.58395 | C13: 51.3 | D13: 48.96 | E13: 53.7 | F13: 38.88 | G13: 39.37 | H13: 31.16 | I13: 0 | J13: 0 | K13: 5 | L13: 0 | M13: 15 | N13: 37.735847 | O13: 1.753938 | P13: 45.528247 | Q13: 84.390127 | R13: 0 | S13: 16.5 | T13: 469.27816
... A129: Iceland | B129: =VLOOKUP(A129,'Bank Z Score'!$C$12:$P$226,14,FALSE) -> 1.276241 | C129: 100 | D129: 100 | E129: 100 | F129: 100 | G129: 100 | H129: 100 | I129: 0 | J129: 0 | K129: 7 | L129: 100.31626 | M129: 10 | N129: 95.238098 | O129: 0 | P129: 0 | Q129: 93.233912 | R129: 0 | S129: 11.5 | T129: 917.28827

Sheet Country Survey Data
A1: Country Name | B1: Country Code | C1: Series Name | D1: Series Code | E1: 2019 [YR2019] | F1: 2020 [YR2020] | G1: 2021 [YR2021] | H1: 2022 [YR2022] | I1: 2023 [YR2023] | J1: Max
A2: Afghanistan | B2: AFG | C2: Account ownership at a financial institution or with a mobile-money-service provider (% of population ages 15+) | D2: FX.OWN.TOTL.ZS | G2: 9.65 | J2: =MAX(E2:I2) -> 9.65
A3: Afghanistan | B3: AFG | C3: Account ownership at a financial institution or with a mobile-money-service provider, female (% of population ages 15+) | D3: FX.OWN.TOTL.FE.ZS | G3: 4.7 | J3: =MAX(E3:I3) -> 4.7
A4: Afghanistan | B4: AFG | C4: Account ownership at a financial institution or with a mobile-money-service provider, male (% of population ages 15+) | D4: FX.OWN.TOTL.MA.ZS | G4: 14.79 | J4: =MAX(E4:I4) -> 14.79
A5: Afghanistan | B5: AFG | C5: Account ownership at a financial institution or with a mobile-money-service provider, poorest 40% (% of population ages 15+) | D5: FX.OWN.TOTL.40.ZS | G5: 5.86 | J5: =MAX(E5:I5) -> 5.86
A6: Afghanistan | B6: AFG | C6: Account ownership at a financial institution or with a mobile-money-service provider, young adults (% of population ages 15-24) | D6: FX.OWN.TOTL.YG.ZS | G6: 7.55 | J6: =MAX(E6:I6) -> 7.55
A7: Afghanistan | B7: AFG | C7: Account ownership at a financial institution or with a mobile-money-service provider, primary education or less (% of population ages 15+) | D7: FX.OWN.TOTL.PL.ZS | G7: 5.18 | J7: =MAX(E7:I7) -> 5.18
A8: Afghanistan | B8: AFG | C8: Average working hours of children, working only, ages 7-14 (hours per week) | D8: SL.TLF.0714.WK.TM | J8: =MAX(E8:I8) -> 0
A9: Afghanistan | B9: AFG | C9: Bribery incidence (% of firms experiencing at least one bribe payment request) | D9: IC.FRM.BRIB.ZS | J9: =MAX(E9:I9) -> 0
A10: Afghanistan | B10: AFG | C10: Business extent of disclosure index (0=less disclosure to 10=more disclosure) | D10: IC.BUS.DISC.XQ | E10: 8 | J10: =MAX(E10:I10) -> 8
A11: Afghanistan | B11: AFG | C11: Central government debt, total (% of GDP) | D11: GC.DOD.TOTL.GD.ZS | J11: =MAX(E11:I11) -> 0
A12: Afghanistan | B12: AFG | C12: Compulsory education, duration (years) | D12: SE.COM.DURS | E12: 9 | F12: 9 | G12: 9 | H12: 9 | I12: 9 | J12: =MAX(E12:I12) -> 9
A13: Afghanistan | B13: AFG | C13: Control of Corruption: Percentile Rank | D13: CC.PER.RNK | E13: 5.7142859 | F13: 4.7619047 | G13: 12.380953 | H13: 12.264151 | I13: 13.679245 | J13: =MAX(E13:I13) -> 13.679245
A14: Afghanistan | B14: AFG | C14: Coverage of social safety net programs (% of population) | D14: per_sa_allsa.cov_pop_tot | J14: =MAX(E14:I14) -> 0
A15: Afghanistan | B15: AFG | C15: Coverage of social insurance programs in poorest quintile (% of population) | D15: per_si_allsi.cov_q1_tot | J15: =MAX(E15:I15) -> 0
A16: Afghanistan | B16: AFG | C16: Survival to age 65, female (% of cohort) | D16: SP.DYN.TO65.FE.ZS | E16: 67.952078 | F16: 64.471496 | G16: 62.67188 | H16: 69.906777 | J16: =MAX(E16:I16) -> 69.906777
A17: Afghanistan | B17: AFG | C17: Technicians in R&D (per million people) | D17: SP.POP.TECH.RD.P6 | J17: =MAX(E17:I17) -> 0
A18: Afghanistan | B18: AFG | C18: Time required to start a business (days) | D18: IC.REG.DURS | E18: 8.5 | J18: =MAX(E18:I18) -> 8.5
A19: Algeria | B19: DZA | C19: Account ownership at a financial institution or with a mobile-money-service provider (% of population ages 15+) | D19: FX.OWN.TOTL.ZS | G19: 44.1 | J19: =MAX(E19:I19) -> 44.1
A20: Algeria | B20: DZA | C20: Account ownership at a financial institution or with a mobile-money-service provider, female (% of population ages 15+) | D20: FX.OWN.TOTL.FE.ZS | G20: 31.19 | J20: =MAX(E20:I20) -> 31.19
A21: Algeria | B21: DZA | C21: Account ownership at a financial institution or with a mobile-money-service provider, male (% of population ages 15+) | D21: FX.OWN.TOTL.MA.ZS | G21: 56.83 | J21: =MAX(E21:I21) -> 56.83
A22: Algeria | B22: DZA | C22: Account ownership at a financial institution or with a mobile-money-service provider, poorest 40% (% of population ages 15+) | D22: FX.OWN.TOTL.40.ZS | G22: 31.91 | J22: =MAX(E22:I22) -> 31.91
A23: Algeria | B23: DZA | C23: Account ownership at a financial institution or with a mobile-money-service provider, young adults (% of population ages 15-24) | D23: FX.OWN.TOTL.YG.ZS | G23: 26.72 | J23: =MAX(E23:I23) -> 26.72
A24: Algeria | B24: DZA | C24: Account ownership at a financial institution or with a mobile-money-service provider, primary education or less (% of population ages 15+) | D24: FX.OWN.TOTL.PL.ZS | G24: 38.99 | J24: =MAX(E24:I24) -> 38.99
A25: Algeria | B25: DZA | C25: Average working hours of children, working only, ages 7-14 (hours per week) | D25: SL.TLF.0714.WK.TM | J25: =MAX(E25:I25) -> 0
A26: Algeria | B26: DZA | C26: Bribery incidence (% of firms experiencing at least one bribe payment request) | D26: IC.FRM.BRIB.ZS | J26: =MAX(E26:I26) -> 0
A27: Algeria | B27: DZA | C27: Business extent of disclosure index (0=less disclosure to 10=more disclosure) | D27: IC.BUS.DISC.XQ | E27: 4 | J27: =MAX(E27:I27) -> 4
A28: Algeria | B28: DZA | C28: Central government debt, total (% of GDP) | D28: GC.DOD.TOTL.GD.ZS | J28: =MAX(E28:I28) -> 0
A29: Algeria | B29: DZA | C29: Compulsory education, duration (years) | D29: SE.COM.DURS | E29: 10 | F29: 10 | G29: 10 | H29: 10 | I29: 10 | J29: =MAX(E29:I29) -> 10
A30: Algeria | B30: DZA | C30: Control of Corruption: Percentile Rank | D30: CC.PER.RNK | E30: 28.095238 | F30: 27.619047 | G30: 29.523809 | H30: 27.830189 | I30: 30.188679 | J30: =MAX(E30:I30) -> 30.188679
A31: Algeria | B31: DZA | C31: Coverage of social safety net programs (% of population) | D31: per_sa_allsa.cov_pop_tot | J31: =MAX(E31:I31) -> 0
A32: Algeria | B32: DZA | C32: Coverage of social insurance programs in poorest quintile (% of population) | D32: per_si_allsi.cov_q1_tot | J32: =MAX(E32:I32) -> 0
A33: Algeria | B33: DZA | C33: Survival to age 65, female (% of cohort) | D33: SP.DYN.TO65.FE.ZS | E33: 86.581483 | F33: 83.900669 | G33: 85.956712 | H33: 87.509843 | J33: =MAX(E33:I33) -> 87.509843
A34: Algeria | B34: DZA | C34: Technicians in R&D (per million people) | D34: SP.POP.TECH.RD.P6 | J34: =MAX(E34:I34) -> 0
A35: Algeria | B35: DZA | C35: Time required to start a business (days) | D35: IC.REG.DURS | E35: 18 | J35: =MAX(E35:I35) -> 18
A36: Denmark | B36: DNK | C36: Account ownership at a financial institution or with a mobile-money-service provider (% of population ages 15+) | D36: FX.OWN.TOTL.ZS | G36: 100 | J36: =MAX(E36:I36) -> 100
A37: Denmark | B37: DNK | C37: Account ownership at a financial institution or with a mobile-money-service provider, female (% of population ages 15+) | D37: FX.OWN.TOTL.FE.ZS | G37: 100 | J37: =MAX(E37:I37) -> 100
A38: Denmark | B38: DNK | C38: Account ownership at a financial institution or with a mobile-money-service provider, male (% of population ages 15+) | D38: FX.OWN.TOTL.MA.ZS | G38: 100 | J38: =MAX(E38:I38) -> 100
A39: Denmark | B39: DNK | C39: Account ownership at a financial institution or with a mobile-money-service provider, poorest 40% (% of population ages 15+) | D39: FX.OWN.TOTL.40.ZS | G39: 100 | J39: =MAX(E39:I39) -> 100
A40: Denmark | B40: DNK | C40: Account ownership at a financial institution or with a mobile-money-service provider, young adults (% of population ages 15-24) | D40: FX.OWN.TOTL.YG.ZS | G40: 100 | J40: =MAX(E40:I40) -> 100
...

Sheet Bank Z Score
A1: Series Name | B1: Series Code | C1: Country Name | D1: Country Code | E1: 1990 [YR1990] | F1: 2000 [YR2000] | G1: 2012 [YR2012] | H1: 2013 [YR2013] | I1: 2014 [YR2014] | J1: 2015 [YR2015] | K1: 2016 [YR2016] | L1: 2017 [YR2017] | M1: 2018 [YR2018] | N1: 2019 [YR2019] | O1: 2020 [YR2020] | P1: 2021 [YR2021]
A2: Bank Z-score | B2: GFDD.SI.01 | C2: East Asia & Pacific (IDA total) | D2: DEA | E2: .. | F2: .. | G2: .. | H2: .. | I2: .. | J2: .. | K2: .. | L2: .. | M2: .. | N2: .. | O2: .. | P2: ..
A3: Bank Z-score | B3: GFDD.SI.01 | C3: Europe & Central Asia (IDA total) | D3: DEC | E3: .. | F3: .. | G3: .. | H3: .. | I3: .. | J3: .. | K3: .. | L3: .. | M3: .. | N3: .. | O3: .. | P3: ..
A4: Bank Z-score | B4: GFDD.SI.01 | C4: IBRD only | D4: IBD | E4: .. | F4: .. | G4: .. | H4: .. | I4: .. | J4: .. | K4: .. | L4: .. | M4: .. | N4: .. | O4: .. | P4: ..
A5: Bank Z-score | B5: GFDD.SI.01 | C5: IDA total | D5: IDA | E5: .. | F5: .. | G5: .. | H5: .. | I5: .. | J5: .. | K5: .. | L5: .. | M5: .. | N5: .. | O5: .. | P5: ..
A6: Bank Z-score | B6: GFDD.SI.01 | C6: Latin America & Caribbean (IDA total) | D6: DLA | E6: .. | F6: .. | G6: .. | H6: .. | I6: .. | J6: .. | K6: .. | L6: .. | M6: .. | N6: .. | O6: .. | P6: ..
A7: Bank Z-score | B7: GFDD.SI.01 | C7: Least developed countries: UN classification | D7: LDC | E7: .. | F7: .. | G7: .. | H7: .. | I7: .. | J7: .. | K7: .. | L7: .. | M7: .. | N7: .. | O7: .. | P7: ..
A8: Bank Z-score | B8: GFDD.SI.01 | C8: Middle East & North Africa (IDA total) | D8: DMN | E8: .. | F8: .. | G8: .. | H8: .. | I8: .. | J8: .. | K8: .. | L8: .. | M8: .. | N8: .. | O8: .. | P8: ..
A9: Bank Z-score | B9: GFDD.SI.01 | C9: Small island developing states: UN classification | D9: SID | E9: .. | F9: .. | G9: .. | H9: .. | I9: .. | J9: .. | K9: .. | L9: .. | M9: .. | N9: .. | O9: .. | P9: ..
A10: Bank Z-score | B10: GFDD.SI.01 | C10: South Asia (IDA total) | D10: DSA | E10: .. | F10: .. | G10: .. | H10: .. | I10: .. | J10: .. | K10: .. | L10: .. | M10: .. | N10: .. | O10: .. | P10: ..
A11: Bank Z-score | B11: GFDD.SI.01 | C11: Sub-Saharan Africa (IDA total) | D11: DSS | E11: .. | F11: .. | G11: .. | H11: .. | I11: .. | J11: .. | K11: .. | L11: .. | M11: .. | N11: .. | O11: .. | P11: ..
A12: Bank Z-score | B12: GFDD.SI.01 | C12: Afghanistan | D12: AFG | E12: .. | F12: .. | G12: 18.89366 | H12: 18.98689 | I12: 16.59461 | J12: 16.86543 | K12: 19.55651 | L12: 17.73415 | M12: 17.00372 | N12: 19.31851 | O12: 17.68296 | P12: 24.91561
A13: Bank Z-score | B13: GFDD.SI.01 | C13: Albania | D13: ALB | E13: .. | F13: 22.70429 | G13: 22.32134 | H13: 22.08734 | I13: 22.15308 | J13: 22.14953 | K13: 23.78067 | L13: 21.7047 | M13: 19.98183 | N13: 20.55072 | O13: 20.24314 | P13: 19.05608
A14: Bank Z-score | B14: GFDD.SI.01 | C14: Algeria | D14: DZA | E14: .. | F14: 8.788944 | G14: 20.49009 | H14: 20.54717 | I14: 18.82034 | J14: 19.96733 | K14: 22.13776 | L14: 23.12142 | M14: 24.28966 | N14: 22.43565 | O14: 24.82232 | P14: ..
A15: Bank Z-score | B15: GFDD.SI.01 | C15: Andorra | D15: AND | E15: .. | F15: 32.94271 | G15: 28.4331 | H15: 29.63145 | I15: 28.30516 | J15: 31.50115 | K15: 21.04386 | L15: 25.39093 | M15: 25.15558 | N15: 27.46493 | O15: 29.13949 | P15: ..
A16: Bank Z-score | B16: GFDD.SI.01 | C16: Angola | D16: AGO | E16: .. | F16: .. | G16: 9.03674 | H16: 9.455144 | I16: 8.564436 | J16: 8.2767 | K16: 8.226519 | L16: 8.975831 | M16: 12.03643 | N16: 15.27698 | O16: 8.44287 | P16: 15.54836
A17: Bank Z-score | B17: GFDD.SI.01 | C17: Antigua and Barbuda | D17: ATG | E17: .. | F17: 18.29223 | G17: .. | H17: .. | I17: .. | J17: .. | K17: .. | L17: .. | M17: .. | N17: .. | O17: .. | P17: ..
A18: Bank Z-score | B18: GFDD.SI.01 | C18: Argentina | D18: ARG | E18: .. | F18: 4.915412 | G18: 7.497633 | H18: 7.65534 | I18: 8.4206 | J18: 8.448619 | K18: 7.426713 | L18: 7.50613 | M18: 7.21939 | N18: 9.317062 | O18: 9.249464 | P18: 9.083421
A19: Bank Z-score | B19: GFDD.SI.01 | C19: Armenia | D19: ARM | E19: .. | F19: 9.300473 | G19: 16.44 | H19: 15.40515 | I19: 13.38436 | J19: 13.70702 | K19: 14.90953 | L19: 14.88844 | M19: 14.4391 | N19: 14.2648 | O19: 12.8254 | P19: 12.31924
A20: Bank Z-score | B20: GFDD.SI.01 | C20: Aruba | D20: ABW | E20: .. | F20: .. | G20: .. | H20: .. | I20: .. | J20: .. | K20: .. | L20: .. | M20: .. | N20: .. | O20: .. | P20: ..
A21: Bank Z-score | B21: GFDD.SI.01 | C21: Australia | D21: AUS | E21: .. | F21: 10.741 | G21: 13.89547 | H21: 13.73787 | I21: 13.48903 | J21: 13.33152 | K21: 12.99751 | L21: 13.63942 | M21: 13.97005 | N21: 13.46988 | O21: 13.24647 | P21: 14.14526
A22: Bank Z-score | B22: GFDD.SI.01 | C22: Austria | D22: AUT | E22: .. | F22: 19.72025 | G22: 22.59156 | H22: 27.50797 | I22: 26.82064 | J22: 30.07913 | K22: 32.52342 | L22: 34.54782 | M22: 35.68405 | N22: 36.66615 | O22: 31.84211 | P22: 30.90653
A23: Bank Z-score | B23: GFDD.SI.01 | C23: Azerbaijan | D23: AZE | E23: .. | F23: 7.194723 | G23: 5.090334 | H23: 5.775506 | I23: 6.574747 | J23: 1.471681 | K23: 3.811226 | L23: 5.979235 | M23: 5.460769 | N23: 5.426664 | O23: 5.39014 | P23: 4.744682
A24: Bank Z-score | B24: GFDD.SI.01 | C24: Bahamas, The | D24: BHS | E24: .. | F24: 16.78018 | G24: 17.84337 | H24: 17.16841 | I24: 12.99366 | J24: 15.2718 | K24: 16.34087 | L24: 17.4459 | M24: 17.77508 | N24: 15.69522 | O24: 13.54524 | P24: 13.22551
A25: Bank Z-score | B25: GFDD.SI.01 | C25: Bahrain | D25: BHR | E25: .. | F25: 6.692049 | G25: 7.485067 | H25: 8.06957 | I25: 8.107829 | J25: 8.311663 | K25: 8.660233 | L25: 8.824603 | M25: 8.34296 | N25: 8.855496 | O25: 7.434731 | P25: 7.814275
A26: Bank Z-score | B26: GFDD.SI.01 | C26: Bangladesh | D26: BGD | E26: .. | F26: 13.40177 | G26: 15.32456 | H26: 17.39595 | I26: 16.54761 | J26: 17.40561 | K26: 14.90764 | L26: 14.76704 | M26: 14.11607 | N26: 14.0125 | O26: 13.64848 | P26: 12.7788
A27: Bank Z-score | B27: GFDD.SI.01 | C27: Barbados | D27: BRB | E27: .. | F27: 16.32253 | G27: 16.24925 | H27: 17.49197 | I27: 18.66439 | J27: 16.59562 | K27: 17.0683 | L27: 14.93573 | M27: .. | N27: .. | O27: 13.33107 | P27: 13.9577
A28: Bank Z-score | B28: GFDD.SI.01 | C28: Belarus | D28: BLR | E28: .. | F28: 37.27287 | G28: 20.06017 | H28: 20.09407 | I28: 19.87708 | J28: 16.10306 | K28: 16.9789 | L28: 18.70259 | M28: 18.86887 | N28: 18.61382 | O28: 17.6692 | P28: 17.12395
A29: Bank Z-score | B29: GFDD.SI.01 | C29: Belgium | D29: BEL | E29: .. | F29: 7.882141 | G29: 12.44705 | H29: 14.23736 | I29: 14.36594 | J29: 15.67043 | K29: 16.37894 | L29: 18.16668 | M29: 17.78204 | N29: 18.25408 | O29: 16.52576 | P29: 15.4485
A30: Bank Z-score | B30: GFDD.SI.01 | C30: Belize | D30: BLZ | E30: .. | F30: .. | G30: .. | H30: .. | I30: .. | J30: 8.833839 | K30: 8.181306 | L30: 10.25167 | M30: 10.3004 | N30: 9.817226 | O30: 6.773071 | P30: ..
A31: Bank Z-score | B31: GFDD.SI.01 | C31: Benin | D31: BEN | E31: .. | F31: 12.91856 | G31: 14.32835 | H31: 12.0286 | I31: .. | J31: 9.922345 | K31: 8.608675 | L31: 7.838364 | M31: 11.88513 | N31: 11.90162 | O31: .. | P31: ..
A32: Bank Z-score | B32: GFDD.SI.01 | C32: Bermuda | D32: BMU | E32: .. | F32: .. | G32: 25.20727 | H32: 19.62559 | I32: 22.03606 | J32: 22.614 | K32: 21.16991 | L32: 23.82868 | M32: 26.09518 | N32: 22.26934 | O32: 20.18716 | P32: 18.72809
A33: Bank Z-score | B33: GFDD.SI.01 | C33: Bhutan | D33: BTN | E33: .. | F33: .. | G33: .. | H33: 23.08103 | I33: 21.42044 | J33: 21.60773 | K33: 19.42956 | L33: 18.26993 | M33: 18.50756 | N33: 16.36592 | O33: 11.20364 | P33: 12.46007
A34: Bank Z-score | B34: GFDD.SI.01 | C34: Bolivia | D34: BOL | E34: .. | F34: 10.30406 | G34: 12.22055 | H34: 11.04395 | I34: 10.94711 | J34: 10.18686 | K34: 10.6695 | L34: 9.5578 | M34: 9.244541 | N34: 9.595237 | O34: 8.104293 | P34: 8.322064
A35: Bank Z-score | B35: GFDD.SI.01 | C35: Bosnia and Herzegovina | D35: BIH | E35: .. | F35: 22.70304 | G35: 18.76711 | H35: 17.76029 | I35: 18.65933 | J35: 17.95149 | K35: 18.51242 | L35: 18.97532 | M35: 17.08238 | N35: 16.79659 | O35: 15.29625 | P35: 15.29255
A36: Bank Z-score | B36: GFDD.SI.01 | C36: Botswana | D36: BWA | E36: .. | F36: 9.010239 | G36: 8.96806 | H36: 9.692696 | I36: 9.374351 | J36: 8.128801 | K36: 8.435014 | L36: 8.347235 | M36: 8.37 | N36: 8.500373 | O36: 8.288707 | P36: 9.001644
A37: Bank Z-score | B37: GFDD.SI.01 | C37: Brazil | D37: BRA | E37: .. | F37: 15.42642 | G37: 14.96336 | H37: 14.53454 | I37: 14.76513 | J37: 15.58268 | K37: 15.95113 | L37: 16.98571 | M37: 16.93262 | N37: 18.54721 | O37: 15.71668 | P37: 16.35463
A38: Bank Z-score | B38: GFDD.SI.01 | C38: British Virgin Islands | D38: VGB | E38: .. | F38: .. | G38: .. | H38: .. | I38: .. | J38: .. | K38: .. | L38: .. | M38: .. | N38: .. | O38: .. | P38: ..
A39: Bank Z-score | B39: GFDD.SI.01 | C39: Brunei Darussalam | D39: BRN | E39: .. | F39: .. | G39: .. | H39: .. | I39: .. | J39: .. | K39: .. | L39: .. | M39: .. | N39: .. | O39: .. | P39: ..
A40: Bank Z-score | B40: GFDD.SI.01 | C40: Bulgaria | D40: BGR | E40: .. | F40: 14.27572 | G40: 8.641701 | H40: 8.415757 | I40: 8.748191 | J40: 8.708157 | K40: 9.149668 | L40: 8.928413 | M40: 8.719459 | N40: 8.123374 | O40: 7.749717 | P40: 7.869337
...
